Workbook

Sheet READ ME "Project Overview"
A1: Personal Finance Analysis Dashboard (2022–2024) "Read Me"
A2: This workbook provides a multi-year analysis of personal income, expenses, crypto holdings, and earning activities across both traditional and digital income streams. The portfolio uses structured example ledger data and dashboard visuals to evaluate net savings, financial efficiency, and year-over-year performance trends. This portfolio and analysis is based on real personal experiences and transactions, however modified into example data for other use. I created this to help understand where, why and what I was doing with my money during a time I went to college and worked.
A7: Project Objectives
A8: Track active and passive income from multiple sources.
A9: Maintain a detailed expense ledger to monitor spending habits.
A10: Track and value cryptocurrency holdings and earnings over time.
A11: Summarize financial performance using interactive dashboards.
A12: Analyze year-over-year growth, savings rates, and cash flow patterns.
A15: Tools & Methods Used
A16: Area | B16: Details
A17: Software | B17: Microsoft Excel, Transitions into SQL
A18: Visualizations | B18: Pie charts, time-series charts, category summaries, net income dashboards
A19: Data Management | B19: Ledger design, multi-sheet data structure, reference tables
A22: Sheet Overview
A23: Sheet Name | B23: Purpose & Description
A24: 2023–24 Portfolio (Dashboard) | B24: Dashboard summarizing Year 2 financial performance with year-over-year comparison metrics. Measures financial progress, spending adjustments, and gains in overall net worth.
A25: 2022–23 Portfolio (Dashboard) | B25: Dashboard summarizing Year 1 financial performance, including total income vs. expenses, crypto valuations, and expense category breakdowns. Highlights net savings and financial patterns.
A26: Crypto Ledger Wallet | B26: Maintains balances of cryptocurrency holdings across wallets and exchanges. Linked to market pricing to produce net worth and performance summaries.
A27: Expenses | B27: Categorized expense ledger tracking dates, vendors, and amounts spent. Supports spending analysis, budgeting, and savings-rate tracking. "Not Included in PDF"
A28: Work Hours | B28: Tracks hours worked, pay rates, and dates across different job roles. Used to compute annual earned income and compare labor earnings to passive income sources. "Not Included in PDF"
A29: Earning Claims | B29: Transaction-level log of income from online sources (survey platforms, apps, freelancing, etc.). Supports income verification, time-value analysis, and platform comparison.
A30: General Crypto Earnings | B30: Records earnings generated from platforms including staking, mining, and rewards. Used to measure passive income growth and annual crypto revenue.
A31: Earning Claims | B31: Transaction-level log of income from online sources (survey platforms, apps, freelancing, etc.). Supports income verification, time-value analysis, and platform comparison.
A32: Crypto Market Price | B32: Reference price sheet used to track cryptocurrency market values. Enables real-time valuation of crypto holdings and supports return-on-investment calculations across the portfolio.
A35: Key Insights Demonstrated
A36: Ability to design and structure financial tracking systems from raw data.
A37: Strong understanding of personal finance categorization and cost analysis.
A38: Proficiency using Excel for analytical reporting and dashboard visualization.
A39: Demonstrated ability to track and evaluate multi-stream income and investments.
A40: Capability to convert personal finance data into business-quality reporting.
A43: Next Development Phase: SQL Migration (In Progress)
A44: This workbook is being migrated into a structured SQL database to enable:
A45: Automated financial reporting
A46: Query-based expense categorization
A47: Performance dashboards for the web/mobile environment

Sheet 2023-24 Portfolio "Dashboard"
A2: 2023-24 Personal Finance Analysis Dashboard
B4: 4
A5: Bank | B5: Credit | C5: Cash | D5: Total | E5: Owed
A6: 873.95 | B6: 0 | C6: =E7+E8+C8 -> 1957 | D6: =(A6+C6)-B6 -> 2830.95 | E6: 0
E7: 501
A8: Expenses By Month | C8: 520 | D8: Folder | E8: 936
A9: Months | B9: Expenses | C9: Gross Income | D9: Net | E9: Savings
A10: June | B10: =Expenses!$B$301 -> -1741.25 | C10: =SUM(Expenses!$C$301:$E$301) -> 2590.25 | D10: =C10+B10 -> 849 | E10: -
A11: July | B11: =Expenses!$B$302 -> -1727.68 | C11: =SUM(Expenses!$C$302:$E$302) -> 1657 | D11: =C11+B11 -> -70.68 | E11: -
A12: August | B12: =Expenses!$B$303 -> -1866.74 | C12: =SUM(Expenses!$C$303:$E$303) -> 3038.75 | D12: =C12+B12 -> 1172.01 | E12: -
A13: September | B13: =Expenses!$B$304 -> -911.95 | C13: =SUM(Expenses!$C$304:$E$304) -> 2964.25 | D13: =C13+B13 -> 2052.3 | E13: -
A14: October | B14: =Expenses!$B$305 -> -996.32 | C14: =SUM(Expenses!$C$305:$E$305) -> 3298 | D14: =C14+B14 -> 2301.68 | E14: -
A15: November | B15: =Expenses!$B$306 -> -963.7 | C15: =SUM(Expenses!$C$306:$E$306) -> 3322.25 | D15: =C15+B15 -> 2358.55 | E15: -
A16: December | B16: =Expenses!$B$307 -> -1835.44 | C16: =SUM(Expenses!$C$307:$E$307) -> 1526.625 | D16: =C16+B16 -> -308.815 | E16: -
A17: January | B17: =Expenses!$B$308 -> -869.93 | C17: =SUM(Expenses!$C$308:$E$308) -> 2044.5 | D17: =C17+B17 -> 1174.57 | E17: -
A18: February | B18: =Expenses!$B$309 -> -2345.87 | C18: =SUM(Expenses!$C$309:$E$309) -> 1763.875 | D18: =C18+B18 -> -581.995 | E18: -
A19: March | B19: =Expenses!$B$310 -> -1581.39 | C19: =SUM(Expenses!$C$310:$E$310) -> 2869.625 | D19: =C19+B19 -> 1288.235 | E19: -
A20: April | B20: =Expenses!$B$311 -> -1280.14 | C20: =SUM(Expenses!$C$311:$E$311) -> 2336.75 | D20: =C20+B20 -> 1056.61 | E20: -
A21: May | B21: =Expenses!$B$312 -> -1674.68 | C21: =SUM(Expenses!$C$312:$E$312) -> 992.5 | D21: =C21+B21 -> -682.18 | E21: -
A22: Totals | B22: =SUM(B10:B21) -> -17795.09 | C22: =SUM(C10:C21) -> 28404.375 | D22: =SUM(D10:D21) -> 10609.285 | E22: 0
A23: Expenses By Category
A24: Category | B24: June Expenses | C24: July Expenses | D24: Auguest | E24: September | F24: October | G24: November | H24: December | I24: January | J24: February | K24: March | L24: April | M24: May | N24: Total
A25: Flights | B25: =Expenses!C188 -> -227.8 | C25: =Expenses!H188 -> -300 | D25: =Expenses!M188 -> 0 | E25: =Expenses!R188 -> 0 | F25: =Expenses!W188 -> 0 | G25: =Expenses!AB188 -> -69.94 | H25: =Expenses!AG188 -> 0 | I25: =Expenses!AL188 -> 0 | J25: =Expenses!AQ188 -> -14.38 | K25: =Expenses!AV188 -> 0 | L25: =Expenses!BA188 -> 0 | M25: =Expenses!BF188 -> 0 | N25: =SUM(B25:L25) -> -612.12
A26: Gas | B26: =Expenses!C197 -> -116 | C26: =Expenses!H196 -> -144.05 | D26: =Expenses!M196 -> -90.01 | E26: =Expenses!R195 -> -50 | F26: =Expenses!W196 -> -100 | G26: =Expenses!AB196 -> -130 | H26: =Expenses!AG197 -> -90 | I26: =Expenses!AL197 -> -140 | J26: =Expenses!AQ197 -> -92.25 | K26: =Expenses!AV197 -> -145 | L26: =Expenses!BA197 -> -166 | M26: =Expenses!BF197 -> -165 | N26: =SUM(B26:L26) -> -1263.31
A27: Gas Station Food | B27: =Expenses!C215 -> -186.31 | C27: =Expenses!H214 -> -150.24 | D27: =Expenses!M215 -> -97.48 | E27: =Expenses!R212 -> -120.98 | F27: =Expenses!W217 -> -104.15 | G27: =Expenses!AB211 -> -43.29 | H27: =Expenses!AG215 -> -94.48 | I27: =Expenses!AL212 -> -86.07 | J27: =Expenses!AQ210 -> -42.63 | K27: =Expenses!AV216 -> -145.67 | L27: =Expenses!BA215 -> -86.28 | M27: =Expenses!BF218 -> -142.25 | N27: =SUM(B27:L27) -> -1157.58
A28: Reg. Store | B28: =Expenses!C225 -> -296.57 | C28: =Expenses!H221 -> -149.38 | D28: =Expenses!M225 -> -135.11 | E28: =Expenses!R222 -> -138.86 | F28: =Expenses!W229 -> -145.27 | G28: =Expenses!AB221 -> -49.52 | H28: =Expenses!AG226 -> -195.29 | I28: =Expenses!AL219 -> -154.33 | J28: =Expenses!AQ230 -> -517.9 | K28: =Expenses!AV225 -> -28.12 | L28: =Expenses!BA225 -> -114.91 | M28: =Expenses!BF229 -> -186.76 | N28: =SUM(B28:L28) -> -1925.26
A29: Restaurants | B29: =Expenses!C249 -> -608.86 | C29: =Expenses!H243 -> -588.75 | D29: =Expenses!M243 -> -340.93 | E29: =Expenses!R231 -> -88.7 | F29: =Expenses!W244 -> -264.45 | G29: =Expenses!AB238 -> -137.03 | H29: =Expenses!AG234 -> -128.03 | I29: =Expenses!AL232 -> -202.13 | J29: =Expenses!AQ255 -> -447.88 | K29: =Expenses!AV244 -> -346.97 | L29: =Expenses!BA252 -> -642.94 | M29: =Expenses!BF250 -> -534.65 | N29: =SUM(B29:L29) -> -3796.67
A30: Bars | B30: =Expenses!C255 -> -120 | C30: =Expenses!H249 -> -120 | D30: =Expenses!M250 -> -152 | E30: =Expenses!R237 -> -200 | F30: =Expenses!W250 -> 0 | G30: =Expenses!AB244 -> 0 | H30: =Expenses!AG240 -> 0 | I30: =Expenses!AL241 -> -94.35 | J30: =Expenses!AQ279 -> -784.83 | K30: =Expenses!AV273 -> -558.29 | L30: =Expenses!BA270 -> -175.92 | M30: =Expenses!BF267 -> -306.3 | N30: =SUM(B30:L30) -> -2205.39
A31: Activities | B31: =Expenses!C262 -> -124.56 | C31: =Expenses!H256 -> -82.21 | D31: =Expenses!M263 -> -462.81 | E31: =Expenses!R243 -> -32 | F31: =Expenses!W256 -> -40 | G31: =Expenses!AB251 -> -437.95 | H31: =Expenses!AG246 -> -1080 | I31: =Expenses!AL247 -> -35 | J31: =Expenses!AQ289 -> -254.46 | K31: =Expenses!AV284 -> -81.5 | L31: =Expenses!BA277 -> -69 | M31: =Expenses!BF274 -> -85.5 | N31: =SUM(B31:L31) -> -2699.49
A32: Gifts | B32: =Expenses!C268 -> 0 | C32: =Expenses!H262 -> 0 | D32: =Expenses!M269 -> -300 | E32: =Expenses!R249 -> 0 | F32: =Expenses!W262 -> -28.18 | G32: =Expenses!AB257 -> 0 | H32: =Expenses!AG252 -> 0 | I32: =Expenses!AL253 -> 0 | J32: =Expenses!AQ295 -> 0 | K32: =Expenses!AV290 -> 0 | L32: =Expenses!BA283 -> 0 | M32: =Expenses!BF280 -> 0 | N32: =SUM(B32:L32) -> -328.18
A33: Other | B33: =Expenses!C275 -> -61.15 | C33: =Expenses!H271 -> -193.05 | D33: =Expenses!M278 -> -288.4 | E33: =Expenses!R260 -> -281.41 | F33: =Expenses!W273 -> -314.27 | G33: =Expenses!AB267 -> -95.97 | H33: =Expenses!AG262 -> -247.64 | I33: =Expenses!AL264 -> -158.05 | J33: =Expenses!AQ304 -> -191.54 | K33: =Expenses!AV301 -> -275.84 | L33: =Expenses!BA294 -> -25.09 | M33: =Expenses!BF292 -> -254.22 | N33: =SUM(B33:L33) -> -2132.41
A34: School | B34: =Expenses!C281 -> 0 | C34: =Expenses!H277 -> -3315 | D34: =Expenses!M284 -> 0 | E34: =Expenses!R267 -> -69.32 | F34: =Expenses!W279 -> 0 | G34: =Expenses!AB273 -> -1900 | H34: =Expenses!AG268 -> -20.84 | I34: =Expenses!AL270 -> -264.81 | J34: =Expenses!AQ310 -> -19.99 | K34: =Expenses!AV307 -> -126.57 | L34: =Expenses!BA302 -> -176.6 | M34: =Expenses!BF300 -> -114.95 | N34: =SUM(B34:L34) -> -5893.13
A35: Reacuuring Investments | B35: =Expenses!C295 -> -125.05 | C35: =Expenses!H290 -> -114.65 | D35: =Expenses!M298 -> -75.81 | E35: =Expenses!R279 -> -66.17 | F35: =Expenses!W293 -> -68.73 | G35: =Expenses!AB287 -> -110.4 | H35: =Expenses!AG282 -> -126.24 | I35: =Expenses!AL288 -> -95.26 | J35: =Expenses!AQ329 -> -104.98 | K35: =Expenses!AV327 -> -116.1 | L35: =Expenses!BA324 -> -140.83 | M35: =Expenses!BF322 -> -135.1 | N35: =SUM(B35:L35) -> -1144.22
A36: Total Expenses (All) | B36: =SUM(B25:B35) -> -1866.3 | C36: =SUM(C25:C35) -> -5157.33 | D36: =SUM(D25:D35) -> -1942.55 | E36: =SUM(E25:E35) -> -1047.44 | F36: =SUM(F25:F35) -> -1065.05 | G36: =SUM(G25:G35) -> -2974.1 | H36: =SUM(H25:H35) -> -1982.52 | I36: =SUM(I25:I35) -> -1230 | ... N36: =SUM(N25:N35) -> -23157.76
A37: Crypto Asset Totals and Earnings
A38: Crypto Exchanges | B38: ='Crypto Ledger Wallet'!D16 -> 934.98906 | C38: NFT Asset Total (Future Return)
A39: Crypto Wallets | B39: ='Crypto Ledger Wallet'!D37 -> 295.56259 | C39: ='Crypto Ledger Wallet'!I104 -> 3852.0723
A40: Crypto Staking | B40: ='Crypto Ledger Wallet'!D47 -> 29.531828 | C40: Passive Earnings (AVG./Day)
A41: Crypto App Miners | B41: ='Crypto Ledger Wallet'!I61 -> 966.95465 | C41: {=Table34[Total Passive Earnings ($/Day)]} -> 3.7860646
A42: GPU/CPU & Data Miners | B42: ='Crypto Ledger Wallet'!D60 -> 223.22833 | C42: Passive Earnings (AVG./Week)
...

Sheet 2022-23 Portfolio "Dashboard"
A2: 2022-23 Personal Finance Analysis Dashboard
A5: Bank | B5: Credit | C5: Cash | D5: Total | E5: Owed
A6: 1185.12 | B6: 0 | C6: 256 | D6: =('2022-23 Portfolio "Dashboard"'!$A6+'2022-23 Portfolio "Dashboard"'!$C6)-'2022-23 Portfolio "Dashboard"'!$B6 -> 1441.12 | E6: 45
A8: Expenses By Month
A9: Months | B9: Expenses | C9: Gross Income | D9: Net | E9: Savings
A10: June | B10: =Expenses!$A$157 -> -995.4 | C10: =SUM(Expenses!$B$157:$D$157) -> 1943.45 | D10: ='2022-23 Portfolio "Dashboard"'!$C10+('2022-23 Portfolio "Dashboard"'!$B10) -> 948.05 | E10: -
A11: July | B11: =Expenses!$A$160 -> -1233.7 | C11: =SUM(Expenses!$B$160:$D$160) -> 2782.5 | D11: ='2022-23 Portfolio "Dashboard"'!$C11+('2022-23 Portfolio "Dashboard"'!$B11) -> 1548.8 | E11: -
A12: August | B12: =Expenses!$A$163 -> -881.65 | C12: =SUM(Expenses!$B$163:$D$163) -> 2579.25 | D12: ='2022-23 Portfolio "Dashboard"'!$C12+('2022-23 Portfolio "Dashboard"'!$B12) -> 1697.6 | E12: -
A13: September | B13: =Expenses!$A$166 -> -1516.86 | C13: =SUM(Expenses!$B$166:$D$166) -> 3384 | D13: ='2022-23 Portfolio "Dashboard"'!$C13+('2022-23 Portfolio "Dashboard"'!$B13) -> 1867.14 | E13: -
A14: October | B14: =Expenses!$A$169 -> -1375.68 | C14: =SUM(Expenses!$B$169:$D$169) -> 1130 | D14: ='2022-23 Portfolio "Dashboard"'!$C14+('2022-23 Portfolio "Dashboard"'!$B14) -> -245.68 | E14: -
A15: November | B15: =Expenses!$A$172 -> -1206.44 | C15: =SUM(Expenses!$B$172:$D$172) -> 1189.5 | D15: ='2022-23 Portfolio "Dashboard"'!$C15+('2022-23 Portfolio "Dashboard"'!$B15) -> -16.94 | E15: -
A16: December | B16: =Expenses!$F$157 -> -2427.13 | C16: =SUM(Expenses!$G$157:$I$157) -> 1127 | D16: ='2022-23 Portfolio "Dashboard"'!$C16+('2022-23 Portfolio "Dashboard"'!$B16) -> -1300.13 | E16: -
A17: January | B17: =Expenses!$F$160 -> -2015.38 | C17: =SUM(Expenses!$G$160:$I$160) -> 390 | D17: ='2022-23 Portfolio "Dashboard"'!$C17+('2022-23 Portfolio "Dashboard"'!$B17) -> -1625.38 | E17: -
A18: February | B18: =Expenses!$F$163 -> -1031.88 | C18: =SUM(Expenses!$G$163:$I$163) -> 1041 | D18: ='2022-23 Portfolio "Dashboard"'!$C18+('2022-23 Portfolio "Dashboard"'!$B18) -> 9.12 | E18: -
A19: March | B19: =Expenses!$F$166 -> -1984.81 | C19: =SUM(Expenses!$G$166:$I$166) -> 1020 | D19: ='2022-23 Portfolio "Dashboard"'!$C19+('2022-23 Portfolio "Dashboard"'!$B19) -> -964.81 | E19: -
A20: April | B20: =Expenses!$F$169 -> -669.2 | C20: =SUM(Expenses!$G$169:$I$169) -> 1840.5 | D20: ='2022-23 Portfolio "Dashboard"'!$C20+('2022-23 Portfolio "Dashboard"'!$B20) -> 1171.3 | E20: -
A21: May | B21: =Expenses!$F$172 -> -1211.14 | C21: =SUM(Expenses!$G$172:$I$172) -> 2515.5 | D21: ='2022-23 Portfolio "Dashboard"'!$C21+('2022-23 Portfolio "Dashboard"'!$B21) -> 1304.36 | E21: -
A22: Totals | B22: =SUM('2022-23 Portfolio "Dashboard"'!$B$10:$B$21) -> -16549.27 | C22: =SUM('2022-23 Portfolio "Dashboard"'!$C$10:$C$21) -> 20942.7 | D22: =SUM('2022-23 Portfolio "Dashboard"'!$D$10:$D$21) -> 4393.43 | E22: 0
A23: Expenses By Category
A24: Category | B24: June Expenses | C24: July Expenses | D24: Auguest | E24: September | F24: October | G24: November | H24: December | I24: January | J24: February | K24: March | L24: April | M24: May | N24: Total
A25: Flights | B25: =Expenses!C26 -> 0 | C25: =Expenses!H16 -> 0 | D25: =Expenses!M16 -> 0 | E25: =Expenses!R16 -> -376.2 | F25: =Expenses!W16 -> 0 | G25: =Expenses!AB16 -> -386.2 | H25: =Expenses!AG16 -> 0 | I25: =Expenses!AL16 -> 0 | J25: =Expenses!AQ16 -> 0 | K25: =Expenses!AV16 -> 0 | L25: =Expenses!BA16 -> 0 | M25: =Expenses!BF16 -> 0 | N25: =SUM(B25:M25) -> -762.4
A26: Gas | B26: =Expenses!C35 -> -105.3 | C26: =Expenses!H25 -> -95.3 | D26: =Expenses!M26 -> -113.75 | E26: =Expenses!R25 -> -110.01 | F26: =Expenses!W23 -> -115 | G26: =Expenses!AB25 -> -110.05 | H26: =Expenses!AG26 -> -145.06 | I26: =Expenses!AL25 -> -137.13 | J26: =Expenses!AQ26 -> -175.25 | K26: =Expenses!AV27 -> -165.27 | L26: =Expenses!BA23 -> -66.05 | M26: =Expenses!BF25 -> -120.01 | N26: =SUM(B26:M26) -> -1458.18
A27: Gas Station Food | B27: =Expenses!C62 -> -131.18 | C27: =Expenses!H56 -> -211.29 | D27: =Expenses!M41 -> -85.89 | E27: =Expenses!R47 -> -117.32 | F27: =Expenses!W51 -> -168.24 | G27: =Expenses!AB46 -> -97.81 | H27: =Expenses!AG42 -> -106.17 | I27: =Expenses!AL39 -> -128.69 | J27: =Expenses!AQ40 -> -72.41 | K27: =Expenses!AV44 -> -103.99 | L27: =Expenses!BA36 -> -66.64 | M27: =Expenses!BF40 -> -92.62 | N27: =SUM(B27:M27) -> -1382.25
A28: Reg. Store | B28: =Expenses!C71 -> -61.62 | C28: =Expenses!H63 -> -48.79 | D28: =Expenses!M51 -> -98.25 | E28: =Expenses!R58 -> -122.39 | F28: =Expenses!W59 -> -78.44 | G28: =Expenses!AB53 -> -55.22 | H28: =Expenses!AG49 -> -98.6 | I28: =Expenses!AL50 -> -172.11 | J28: =Expenses!AQ51 -> -117.55 | K28: =Expenses!AV58 -> -436.75 | L28: =Expenses!BA49 -> -184.71 | M28: =Expenses!BF49 -> -214.22 | N28: =SUM(B28:M28) -> -1688.65
A29: Restaurants | B29: =Expenses!C95 -> -284.82 | C29: =Expenses!H85 -> -195.72 | D29: =Expenses!M68 -> -270.12 | E29: =Expenses!R82 -> -239.69 | F29: =Expenses!W93 -> -557.12 | G29: =Expenses!AB71 -> -153.81 | H29: =Expenses!AG73 -> -681.87 | I29: =Expenses!AL70 -> -455.26 | J29: =Expenses!AQ70 -> -279.96 | K29: =Expenses!AV89 -> -742.96 | L29: =Expenses!BA59 -> -85.06 | M29: =Expenses!BF71 -> -466.16 | N29: =SUM(B29:M29) -> -4412.55
A30: Bars | B30: =Expenses!C111 -> -173 | C30: =Expenses!H99 -> -191 | D30: =Expenses!M79 -> -112.64 | E30: =Expenses!R97 -> -201.46 | F30: =Expenses!W105 -> -110 | G30: =Expenses!AB81 -> -80 | H30: =Expenses!AG80 -> -100 | I30: =Expenses!AL80 -> -150 | J30: =Expenses!AQ80 -> -95 | K30: =Expenses!AV96 -> -120 | L30: =Expenses!BA67 -> -160 | M30: =Expenses!BF78 -> -120 | N30: =SUM(B30:M30) -> -1613.1
A31: Activities | B31: =Expenses!C117 -> -6.25 | C31: =Expenses!H109 -> -298.78 | D31: =Expenses!M85 -> 0 | E31: =Expenses!R103 -> -27 | F31: =Expenses!W110 -> -48.38 | G31: =Expenses!AB86 -> -10 | H31: =Expenses!AG88 -> -123 | I31: =Expenses!AL86 -> -56.95 | J31: =Expenses!AQ85 -> -24 | K31: =Expenses!AV107 -> -118.4 | L31: =Expenses!BA74 -> -51.94 | M31: =Expenses!BF86 -> -66.5 | N31: =SUM(B31:M31) -> -831.2
A32: Gifts | B32: =Expenses!C123 -> -19.99 | C32: =Expenses!H115 -> 50 | D32: =Expenses!M91 -> 0 | E32: =Expenses!R109 -> -62.33 | F32: =Expenses!W115 -> -23.04 | G32: =Expenses!AB92 -> 0 | H32: =Expenses!AG113 -> -896.75 | I32: =Expenses!AL92 -> -529.37 | J32: =Expenses!AQ94 -> -18.6 | K32: =Expenses!AV112 -> -58.38 | L32: =Expenses!BA80 -> 0 | M32: =Expenses!BF92 -> -100 | N32: =SUM(B32:M32) -> -1658.46
A33: Other | B33: =Expenses!C132 -> -213.24 | C33: =Expenses!H125 -> -242.82 | D33: =Expenses!M101 -> -201 | E33: =Expenses!R119 -> -260.46 | F33: =Expenses!W125 -> -275.46 | G33: =Expenses!AB102 -> -313.35 | H33: =Expenses!AG122 -> -275.68 | I33: =Expenses!AL104 -> -385.87 | J33: =Expenses!AQ103 -> -148.71 | K33: =Expenses!AV125 -> -239.06 | L33: =Expenses!BA87 -> -54.8 | M33: =Expenses!BF98 -> -31.63 | N33: =SUM(B33:M33) -> -2642.08
A34: School | B34: =Expenses!C138 -> 0 | C34: =Expenses!H131 -> 0 | D34: =Expenses!M107 -> 0 | E34: =Expenses!R125 -> 0 | F34: =Expenses!W131 -> -960 | G34: =Expenses!AB108 -> 0 | H34: =Expenses!AG128 -> 0 | I34: =Expenses!AL110 -> 0 | J34: =Expenses!AQ109 -> -2166 | K34: =Expenses!AV131 -> 0 | L34: =Expenses!BA88 -> 0 | M34: =Expenses!BF104 -> 0 | N34: =SUM(B34:M34) -> -3126
A35: Reacuuring Investments | B35: =Expenses!C152 -> -66 | C35: =Expenses!H146 -> -132.7 | D35: =Expenses!M123 -> -130.95 | E35: =Expenses!R141 -> -137.95 | F35: =Expenses!W146 -> -101.94 | G35: =Expenses!AB124 -> -105.95 | H35: =Expenses!AG145 -> -125.94 | I35: =Expenses!AL129 -> -176 | J35: =Expenses!AQ132 -> -155.02 | K35: =Expenses!AV158 -> -237.14 | L35: =Expenses!BA114 -> -147.17 | M35: =Expenses!BF121 -> -98.04 | N35: =SUM(B35:M35) -> -1614.8
A36: Total Expenses (All) | B36: =SUM(B25:B35) -> -1061.4 | C36: =SUM(C25:C35) -> -1366.4 | D36: =SUM(D25:D35) -> -1012.6 | E36: =SUM(E25:E35) -> -1654.81 | F36: =SUM(F25:F35) -> -2437.62 | G36: =SUM(G25:G35) -> -1312.39 | H36: =SUM(H25:H35) -> -2553.07 | I36: =SUM(I25:I35) -> -2191.38 | ... N36: =SUM(N25:N35) -> -21189.67
A37: Crypto Asset Totals and Earnings
A38: Crypto Exchanges | B38: ='Crypto Ledger Wallet'!D16 -> 934.98906 | C38: NFT Asset Total (Future Return)
A39: Crypto Wallets | B39: ='Crypto Ledger Wallet'!D37 -> 295.56259 | C39: ='Crypto Ledger Wallet'!I104 -> 3852.0723
A40: Crypto Staking | B40: ='Crypto Ledger Wallet'!D47 -> 29.531828 | C40: Passive Earnings (AVG./Day)
A41: Crypto App Miners | B41: ='Crypto Ledger Wallet'!I61 -> 966.95465 | C41: {=Table34[Total Passive Earnings ($/Day)]} -> 3.7860646
A42: GPU/CPU & Data Miners | B42: ='Crypto Ledger Wallet'!D60 -> 223.22833 | C42: Passive Earnings (AVG./Week)
A43: NFT Accounts | B43: ='Crypto Ledger Wallet'!D75 -> 68.120764 | C43: {=Table34[Total Passive Earnings ($/Week)]} -> 25.869213
A44: Investment Apps | B44: ='Crypto Ledger Wallet'!I8 -> 220.46 | C44: Passive Earnings (AVG./Week)
...

Sheet Crypto Ledger Wallet
A1: Fincancial Portfolio: Investment Ledger
A2: Crypto Ledger Wallet
D3: Start Date: (9/27/21)
A4: Crypto Exchanges | D4: Current: 12/26/23 | F4: Investment Apps | I4: Current: 12/26/23
A5: Accounts: Crypto Exchanges | B5: Coin | C5: Amount (Coin) | D5: Amount ($) | F5: Accounts: Invest. Apps | G5: Coin | H5: Amount (Coin) | I5: Amount ($)
A6: Coinbase | F6: Acorns | G6: Dollars | H6: 217.99 | I6: ='Crypto Ledger Wallet'!$H6 -> 217.99
A7: Asset 1 | B7: SOL | C7: 5.01048 | D7: ='Crypto Ledger Wallet'!$C7*'Crypto Market Price Data'!$C$9 -> 620.69826 | F7: Stash | G7: BTC | H7: 2.47 | I7: ='Crypto Ledger Wallet'!$H7 -> 2.47
A8: Asset 2 | B8: GALA | C8: 26342.98 | D8: ='Crypto Ledger Wallet'!$C8*'Crypto Market Price Data'!$C$21 -> 176.83753 | H8: Total: | I8: =SUM('Crypto Ledger Wallet'!$I$6:$I$7) -> 220.46
A9: Binance US | B9: BNB | C9: 0.05605841 | D9: ='Crypto Ledger Wallet'!$C9*'Crypto Market Price Data'!$C$7 -> 45.671908
A10: Huobi Global | B10: BTC | C10: 0 | D10: ='Crypto Ledger Wallet'!$C10*'Crypto Market Price Data'!$C$5 -> 0 | F10: Paid Videos | I10: Current: 12/26/23
A11: Uphold | B11: BAT | C11: 153.486 | D11: ='Crypto Ledger Wallet'!$C11*'Crypto Market Price Data'!$C$13 -> 38.275878 | F11: Accounts: Paid Videos | G11: Coin | H11: Amount (Coin) | I11: Amount ($)
A12: Kucoin | B12: SOUL | C12: 0 | D12: ='Crypto Ledger Wallet'!$C12*'Crypto Market Price Data'!$C$23 -> 0 | F12: HideOutTV | G12: Points | H12: 162.9 | I12: =H12*0.0005 -> 0.08145
A13: Stormgain | B13: BTC | C13: 0.0003 | D13: ='Crypto Ledger Wallet'!$C13*'Crypto Market Price Data'!$C$5 -> 25.4985 | F13: LootTV | G13: Points | H13: 262.6 | I13: =H13*0.0005 -> 0.1313
A14: Crypto.com | B14: CRO | C14: 280.21 | D14: ='Crypto Ledger Wallet'!$C14*'Crypto Market Price Data'!$C$12 -> 28.006989 | H14: Total: | I14: =SUM('Crypto Ledger Wallet'!$I$12:$I$13) -> 0.21275
A15: Uniswap | B15: BTC | C15: 0 | D15: ='Crypto Ledger Wallet'!$C15*'Crypto Market Price Data'!$C$5 -> 0
C16: Total: | D16: =SUM('Crypto Ledger Wallet'!$D$6:$D$15) -> 934.98906 | F16: Faucets/Surveys | I16: Current: 12/26/23
F17: Accounts: Faucets/Surveys | G17: Coin | H17: Amount (Coin) | I17: Amount ($)
A18: Crypto Wallets | D18: Current: 12/26/23 | F18: Cointiply
A19: Accounts: Crypto Wallets | B19: Coin | C19: Amount (Coin) | D19: Amount ($) | F19: - Account 1 (Dan) | G19: BTC | H19: 0.00112252 | I19: ='Crypto Ledger Wallet'!$H19*'Crypto Market Price Data'!$C$5 -> 95.408587
A20: Coinbase Wallet | F20: - Account 2 (Zach) | G20: BTC | H20: 0 | I20: ='Crypto Ledger Wallet'!$H20*'Crypto Market Price Data'!$C$5 -> 0
A21: Asset 1 | B21: ETH | C21: 0.001 | D21: ='Crypto Ledger Wallet'!$C21*'Crypto Market Price Data'!$C$6 -> 2.74059 | F21: Inboxdollars | G21: Dollars | H21: 6.13 | I21: ='Crypto Ledger Wallet'!$H21 -> 6.13
A22: Metamask | F22: Swagbucks | G22: Points | H22: 4081 | I22: ='Crypto Ledger Wallet'!$H22/100 -> 40.81
A23: Etherium Network | F23: PaidViewpoint | G23: Dollars | H23: 46.38 | I23: ='Crypto Ledger Wallet'!$H23 -> 46.38
A24: - Asset 1: Main Account | B24: ETH | C24: 0.0003 | D24: ='Crypto Ledger Wallet'!$C24*'Crypto Market Price Data'!$C$6 -> 0.822177 | I24: =SUM('Crypto Ledger Wallet'!$I$18:$I$23) -> 188.72859
A25: - Asset 2: NFT Accounts | B25: ETH | C25: 0 | D25: ='Crypto Ledger Wallet'!$C25*'Crypto Market Price Data'!$C$6 -> 0
A26: - Asset 3: JumpTask | B26: BNB | C26: 0.0191 | D26: ='Crypto Ledger Wallet'!$C26*'Crypto Market Price Data'!$C$7 -> 15.561152 | F26: Paid Tasks/Surveys Apps | I26: Current: 12/26/23
A27: - Asset 4: Cops & Robber's | B27: ETH | C27: 0.004 | D27: ='Crypto Ledger Wallet'!$C27*'Crypto Market Price Data'!$C$6 -> 10.96236 | F27: Accounts: Paid Tasks/Survey Apps | G27: Coin | H27: Amount (Coin) | I27: Amount ($)
A28: - Asset 5: League of Kingdoms | B28: ETH | C28: 0.005798 | D28: ='Crypto Ledger Wallet'!$C28*'Crypto Market Price Data'!$C$6 -> 15.889941 | F28: Rewards App | G28: Points | H28: 31542 | I28: =(H28/30000)*25 -> 26.285
A29: - Asset 6: The Sandbox | B29: ETH | C29: 0 | D29: ='Crypto Ledger Wallet'!$C29*'Crypto Market Price Data'!$C$6 -> 0 | F29: Google Rewards | G29: Dollars | H29: 0.35 | I29: =H29 -> 0.35
A30: - Asset 7: Gala Games | B30: ETH | C30: 0.002691 | D30: ='Crypto Ledger Wallet'!$C30*'Crypto Market Price Data'!$C$6 -> 7.3749277 | F30: Surveys App | G30: Dollars | H30: 12.1 | I30: =H30 -> 12.1
A31: Ronin | F31: Poll Pay | G31: Dollars | H31: 2.87 | I31: =H31 -> 2.87
A32: Asset 1 | B32: AXS | C32: ='Crypto Claims'!B86 -> 243.3782 | D32: ='Crypto Ledger Wallet'!$C32*'Crypto Market Price Data'!$C$19 -> 242.21144 | F32: Qmee | G32: Dollars | H32: 0 | I32: =H32 -> 0
A33: Electronium | B33: ETH | C33: 0 | D33: ='Crypto Ledger Wallet'!$C33*'Crypto Market Price Data'!$C$6 -> 0 | F33: Influnce | G33: Dollars | H33: 0 | I33: =H33 -> 0
A34: Ecto Wallet | B34: SOUL | C34: 0 | D34: ='Crypto Ledger Wallet'!$C34*'Crypto Market Price Data'!$C$23 -> 0 | F34: Slicethepie | G34: Dollars | H34: 0 | I34: =H34 -> 0
A35: Helium | B35: HNT | C35: 0 | D35: ='Crypto Ledger Wallet'!$C35 -> 0 | H35: Total: | I35: =SUM(I28:I34) -> 41.605
A36: Juicy Field | B36: BTC | C36: 0 | D36: ='Crypto Ledger Wallet'!$C36*'Crypto Market Price Data'!$C$5 -> 0
C37: Total: | D37: =SUM('Crypto Ledger Wallet'!$D$20:$D$36) -> 295.56259 | F37: Receipt Apps | I37: Current: 12/26/23
F38: Accounts: Receipt Apps | G38: Coin | H38: Amount (Coin) | I38: Amount ($)
A39: Staking Wallets | D39: Current: 12/26/23 | F39: Receipt Hog | G39: Points | H39: 3982 | I39: =(H39/6500)*40 -> 24.504615
A40: Accounts: Staking Wallets | B40: Coin | C40: Amount (Coin) | D40: Amount ($) | F40: Receipt Pal | G40: Points | H40: 13965 | I40: =(H40/32250)*100 -> 43.302326
...

Sheet Expenses
A1: Fincancial Portfolio: Expense Data
A2: Expenses
A5: June 2022 Expenses | F5: July 2022 Expenses | K5: August 2022 Expenses | P5: September 2022 Expenses | U5: October 2022 Expenses | Z5: Nobember 2022 Expenses | AE5: December 2022 Expenses | AJ5: January 2023 Expenses | AO5: February 2023 Expenses | AT5: March 2023 Expenses | AY5: April 2023 Expenses | BD5: May 2023 Expenses
A7: Errands | B7: Date | C7: Amount | D7: Notes | F7: Errands | G7: Date | H7: Amount | I7: Notes | K7: Errands | L7: Date | M7: Amount | N7: Notes | P7: Errands | Q7: Date | R7: Amount | S7: Notes | U7: Errands | V7: Date | W7: Amount | X7: Notes | Z7: Errands | AA7: Date | AB7: Amount | AC7: Notes | AE7: Errands | AF7: Date | AG7: Amount | AH7: Notes | AJ7: Errands | AK7: Date | AL7: Amount | AM7: Notes | AO7: Errands | AP7: Date | AQ7: Amount | AR7: Notes | AT7: Errands | AU7: Date | AV7: Amount | AW7: Notes | AY7: Errands | AZ7: Date | BA7: Amount | BB7: Notes | BD7: Errands | BE7: Date | BF7: Amount | BG7: Notes
A8: Dad | B8: 44715 | C8: 20 | F8: Mom: Picked up Car | G8: 44748 | H8: 35 | I8: - In Gas | K8: Dad | L8: 44800 | M8: 20 | P8: Dad | Q8: 44805 | R8: 20 | U8: Dad | V8: 44835 | W8: 40 | Z8: Dad | AA8: 44866 | AB8: 40 | AE8: Dad | AF8: 44896 | AG8: 40 | AJ8: Dad | AK8: 44927 | AL8: 40 | AO8: Dad | AP8: 44958 | AQ8: 40 | AT8: Dad | AU8: 44986 | AV8: 40 | AW8: - Estimate | AY8: Dad | AZ8: 45017 | BA8: 40 | BB8: - Estimate
A9: Lindsey | B9: 44716 | C9: -51.8 | F9: Country Boom Ride | G9: 44750 | H9: 20 | I9: - For Gas | P9: Dad | Q9: 44806 | R9: 20 | S9: - Food | AO9: Mom | AP9: 44985 | AQ9: 100 | AR9: - For Trip & Dog Poop | AT9: Dad | AU9: 44999 | AV9: 80 | AW9: - Estimate
A10: - Paid back | B10: 44716 | C10: 40 | H10: =SUM(H8:H9) -> 55 | M10: =SUM(M8:M9) -> 20 | R10: =SUM(R8:R9) -> 40 | W10: =SUM(W8:W9) -> 40 | AB10: =SUM(AB8:AB9) -> 40 | AG10: =SUM(AG8:AG9) -> 40 | AL10: =SUM(AL8:AL9) -> 40 | AQ10: =SUM(AQ8:AQ9) -> 140 | AV10: =SUM(AV8:AV9) -> 120 | BA10: =SUM(BA8:BA9) -> 40 | BF10: =SUM(BF8:BF9) -> 0
A11: Dad | B11: 44717 | C11: 18
A12: Dad | B12: 44718 | C12: 20
A13: Dad | B13: 44721 | C13: 20 | F13: Flights | G13: Date | H13: Amount | I13: Notes | K13: Flights | L13: Date | M13: Amount | N13: Notes | P13: Flights | Q13: Date | R13: Amount | S13: Notes | U13: Flights | V13: Date | W13: Amount | X13: Notes | Z13: Flights | AA13: Date | AB13: Amount | AC13: Notes | AE13: Flights | AF13: Date | AG13: Amount | AH13: Notes | AJ13: Flights | AK13: Date | AL13: Amount | AM13: Notes | AO13: Flights | AP13: Date | AQ13: Amount | AR13: Notes | AT13: Flights | AU13: Date | AV13: Amount | AW13: Notes | AY13: Flights | AZ13: Date | BA13: Amount | BB13: Notes | BD13: Flights | BE13: Date | BF13: Amount | BG13: Notes
A14: Dad | B14: 44723 | C14: 40 | P14: Plane Ticket | Q14: 44813 | R14: -376.2 | Z14: Flight | AA14: 44871 | AB14: -386.2
A15: Dad | B15: 44724 | C15: 25
A16: Dad | B16: 44729 | C16: 20 | H16: =SUM(H14:H15) -> 0 | M16: =SUM(M14:M15) -> 0 | R16: =SUM(R14:R15) -> -376.2 | W16: =SUM(W14:W15) -> 0 | AB16: =SUM(AB14:AB15) -> -386.2 | AG16: =SUM(AG14:AG15) -> 0 | AL16: =SUM(AL14:AL15) -> 0 | AQ16: =SUM(AQ14:AQ15) -> 0 | AV16: =SUM(AV14:AV15) -> 0 | BA16: =SUM(BA14:BA15) -> 0 | BF16: =SUM(BF14:BF15) -> 0
A17: Dad | B17: 44731 | C17: 20
A18: Dad | B18: 44735 | C18: 20
A19: Dad | B19: 44737 | C19: 20 | F19: Gas | G19: Date | H19: Amount | I19: Notes | K19: Gas | L19: Date | M19: Amount | N19: Notes | P19: Gas | Q19: Date | R19: Amount | S19: Notes | U19: Gas | V19: Date | W19: Amount | X19: Notes | Z19: Gas | AA19: Date | AB19: Amount | AC19: Notes | AE19: Gas | AF19: Date | AG19: Amount | AH19: Notes | AJ19: Gas | AK19: Date | AL19: Amount | AM19: Notes | AO19: Gas | AP19: Date | AQ19: Amount | AR19: Notes | AT19: Gas | AU19: Date | AV19: Amount | AW19: Notes | AY19: Gas | AZ19: Date | BA19: Amount | BB19: Notes | BD19: Gas | BE19: Date | BF19: Amount | BG19: Notes
C20: =SUM(C8:C19) -> 211.2 | F20: Kwik Trip | G20: 44743 | H20: -20.25 | K20: Kwik Trip | L20: 44774 | M20: -20 | P20: Kwik Trip | Q20: 44811 | R20: -20 | U20: Kwik Trip | V20: 44845 | W20: -40 | Z20: Kwik Trip | AA20: 44866 | AB20: -20 | AE20: Kwik Trip | AF20: 44903 | AG20: -25.05 | AJ20: Sun | AK20: 44927 | AL20: -32.31 | AO20: Kwik Trip | AP20: 44958 | AQ20: -25 | AT20: Kwik Trip | AU20: 44991 | AV20: -25.27 | AY20: Kwik Trip | AZ20: 45019 | BA20: -20 | BD20: Kwik Trip | BE20: 45056 | BF20: -30
F21: Kwik Trip | G21: 44750 | H21: -20.05 | K21: Kwik Trip | L21: 44776 | M21: -15 | P21: Kwik Trip | Q21: 44812 | R21: -25 | U21: Kwik Trip | V21: 44852 | W21: -40 | Z21: Kwik Trip | AA21: 44873 | AB21: -20 | AE21: Kwik Trip | AF21: 44908 | AG21: -20 | AJ21: Wawa | AK21: 44932 | AL21: -21.8 | AO21: Kwik Trip | AP21: 44963 | AQ21: -25 | AT21: Kwik Trip | AU21: 44996 | AV21: -40 | AY21: Kwik Trip | AZ21: 45023 | BA21: -25.05 | BD21: Kwik Trip | BE21: 45061 | BF21: -25
F22: Kwik Trip | G22: 44755 | H22: -20 | K22: Kwik Trip | L22: 44785 | M22: -25 | P22: Kwik Trip | Q22: 44823 | R22: -20 | U22: Kwik Trip | V22: 44858 | W22: -35 | Z22: Kwik Trip | AA22: 44878 | AB22: -20.05 | AE22: Kwik Trip | AF22: 44910 | AG22: -30.01 | AJ22: Wawa | AK22: 44932 | AL22: -23.41 | AO22: Kwik Trip | AP22: 44966 | AQ22: -20.25 | AT22: Kwik Trip | AU22: 44996 | AV22: -20 | AY22: Kwik Trip | AZ22: 45029 | BA22: -21 | BD22: Kwik Trip | BE22: 45065 | BF22: -20
A23: Flights | B23: Date | C23: Amount | D23: Notes | F23: Kwik Trip | G23: 44760 | H23: -15 | K23: Kwik Trip | L23: 44788 | M23: -18 | P23: Kwik Trip | Q23: 44828 | R23: -20.01 | W23: =SUM(W20:W22) -> -115 | Z23: Kwik Trip | AA23: 44883 | AB23: -30 | AE23: Kwik Trip | AF23: 44915 | AG23: -25 | AJ23: Circle K | AK23: 44939 | AL23: -29.61 | AO23: Kwik Trip | AP23: 44972 | AQ23: -30 | AT23: Kwik Trip | AU23: 45000 | AV23: -20 | BA23: =SUM(BA20:BA22) -> -66.05 | BD23: Kwik Trip | BE23: 45068 | BF23: -20
F24: Kwik Trip | G24: 44767 | H24: -20 | K24: Kwik Trip | L24: 44793 | M24: -15.75 | P24: Kwik Trip | Q24: 44831 | R24: -25 | Z24: Kwik Trip | AA24: 44895 | AB24: -20 | AE24: Kwik Trip | AF24: 44918 | AG24: -25 | AJ24: Kwik Trip | AK24: 44951 | AL24: -30 | AO24: Kwik Trip | AP24: 44978 | AQ24: -30 | AT24: Kwik Trip | AU24: 45005 | AV24: -20 | BD24: Kwik Trip | BE24: 45076 | BF24: -25.01
H25: =SUM(H20:H24) -> -95.3 | K25: Kwik Trip | L25: 44794 | M25: -20 | R25: =SUM(R20:R24) -> -110.01 | AB25: =SUM(AB20:AB24) -> -110.05 | AE25: Kwik Trip | AF25: 44918 | AG25: -20 | AL25: =SUM(AL20:AL24) -> -137.13 | AO25: Kwik Trip | AP25: 44984 | AQ25: -45 | AR25: - Trip | AT25: Kwik Trip | AU25: 45009 | AV25: -20 | BF25: =SUM(BF20:BF24) -> -120.01
C26: =SUM(C24:C25) -> 0 | M26: =SUM(M20:M25) -> -113.75 | U26: Gas Stations | V26: Date | W26: Amount | X26: Notes | AG26: =SUM(AG20:AG25) -> -145.06 | AQ26: =SUM(AQ20:AQ25) -> -175.25 | AT26: Kwik Trip | AU26: 45012 | AV26: -20 | AY26: Gas Stations | AZ26: Date | BA26: Amount | BB26: Notes
U27: Kwik Trip | V27: 44835 | W27: -3.37 | AV27: =SUM(AV20:AV26) -> -165.27 | AY27: Kwik Trip | AZ27: 45017 | BA27: -5.26
F28: Gas Stations | G28: Date | H28: Amount | I28: Notes | P28: Gas Stations | Q28: Date | R28: Amount | S28: Notes | U28: Kwik Trip | V28: 44836 | W28: -7.58 | Z28: Gas Stations | AA28: Date | AB28: Amount | AC28: Notes | AJ28: Gas Stations | AK28: Date | AL28: Amount | AM28: Notes | AY28: Kwik Trip | AZ28: 45019 | BA28: -5.26 | BD28: Gas Stations | BE28: Date | BF28: Amount | BG28: Notes
A29: Gas | B29: Date | C29: Amount | D29: Notes | F29: Kwik Trip | G29: 44743 | H29: -6.33 | K29: Gas Stations | L29: Date | M29: Amount | N29: Notes | P29: Kwik Trip | Q29: 44806 | R29: -11.09 | U29: Kwik Trip | V29: 44838 | W29: -4.21 | Z29: Kwik Trip | AA29: 44866 | AB29: -4.73 | AE29: Gas Stations | AF29: Date | AG29: Amount | AH29: Notes | AJ29: Circle K | AK29: 44939 | AL29: -47.82 | AO29: Gas Stations | AP29: Date | AQ29: Amount | AR29: Notes | AY29: Kwik Trip | AZ29: 45023 | BA29: -5.26 | BD29: Kwik Trip | BE29: 45047 | BF29: -2.98
A30: Kwik Trip | B30: 44720 | C30: -15 | F30: Kwik Trip | G30: 44744 | H30: -10.52 | K30: Kwik Trip | L30: 44777 | M30: -5.99 | P30: Kwik Trip | Q30: 44808 | R30: -8.1 | U30: Kwik Trip | V30: 44838 | W30: -3.37 | Z30: Kwik Trip | AA30: 44869 | AB30: -8.92 | AE30: Kwik Trip | AF30: 44899 | AG30: -6.31 | AJ30: Kwik Trip | AK30: 44942 | AL30: -7.25 | AO30: Kwik Trip | AP30: 44958 | AQ30: -5.26 | AT30: Gas Stations | AU30: Date | AV30: Amount | AW30: Notes | AY30: Kwik Trip | AZ30: 45029 | BA30: -5.26 | BD30: Kwik Trip | BE30: 45049 | BF30: -5.26
A31: Kwik Trip | B31: 44721 | C31: -25 | F31: Kwik Trip | G31: 44746 | H31: -6.33 | K31: Kwik Trip | L31: 44777 | M31: -9.82 | P31: Kwik Trip | Q31: 44811 | R31: -3.37 | U31: Kwik Trip | V31: 44839 | W31: -8.4 | Z31: Kwik Trip | AA31: 44871 | AB31: -4.21 | AE31: Kwik Trip | AF31: 44903 | AG31: -4.73 | AJ31: Kwik Trip | AK31: 44948 | AL31: -9.45 | AO31: Kwik Trip | AP31: 44963 | AQ31: -7.05 | AT31: Kwik Trip | AU31: 44991 | AV31: -7.25 | AY31: Kwik Trip | AZ31: 45031 | BA31: -8.82 | BD31: Kwik Trip | BE31: 45049 | BF31: -8.82
A32: Kwik Trip | B32: 44726 | C32: -20 | F32: Kwik Trip | G32: 44746 | H32: -6.4 | K32: Kwik Trip | L32: 44780 | M32: -6.81 | P32: Kwik Trip | Q32: 44812 | R32: -6.08 | U32: Kwik Trip | V32: 44840 | W32: -6.9 | Z32: Kwik Trip | AA32: 44873 | AB32: -7.36 | AE32: Kwik Trip | AF32: 44903 | AG32: -5.99 | AJ32: Kwik Trip | AK32: 44949 | AL32: -25.26 | AO32: Kwik Trip | AP32: 44969 | AQ32: -2.83 | AT32: Kwik Trip | AU32: 44993 | AV32: -5.26 | AY32: Kwik Trip | AZ32: 45035 | BA32: -12.19 | BD32: Kwik Trip | BE32: 45052 | BF32: -11.25
A33: Kwik Trip | B33: 44729 | C33: -25.3 | F33: Kwik Trip | G33: 44747 | H33: -10.4 | K33: Kwik Trip | L33: 44782 | M33: -7.56 | P33: Kwik Trip | Q33: 44814 | R33: -6.81 | U33: Kwik Trip | V33: 44841 | W33: -11.09 | Z33: Kwik Trip | AA33: 44873 | AB33: -8.19 | AE33: Kwik Trip | AF33: 44905 | AG33: -12.18 | AJ33: Kwik Trip | AK33: 44950 | AL33: -5.26 | AO33: Kwik Trip | AP33: 44970 | AQ33: -4.73 | AT33: Kwik Trip | AU33: 44994 | AV33: -8.82 | AY33: Kwik Trip | AZ33: 45037 | BA33: -13.34 | BD33: Kwik Trip | BE33: 45054 | BF33: -8.24
A34: Kwik Trip | B34: 44730 | C34: -20 | F34: Kwik Trip | G34: 44748 | H34: -17.04 | K34: Kwik Trip | L34: 44782 | M34: -4 | P34: Kwik Trip | Q34: 44816 | R34: -5.99 | U34: Kwik Trip | V34: 44843 | W34: -11.62 | Z34: Kwik Trip | AA34: 44875 | AB34: -4.21 | AE34: Kwik Trip | AF34: 44910 | AG34: -4.21 | AJ34: Kwik Trip | AK34: 44951 | AL34: -4.73 | AO34: Kwik Trip | AP34: 44974 | AQ34: -11.25 | AT34: Kwik Trip | AU34: 44995 | AV34: -8.82 | AY34: Kwik Trip | AZ34: 45042 | BA34: -5.99 | BD34: Kwik Trip | BE34: 45063 | BF34: -8.1
C35: =SUM(C30:C34) -> -105.3 | F35: Kwik Trip | G35: 44749 | H35: -5.78 | K35: Kwik Trip | L35: 44787 | M35: -11.41 | P35: Kwik Trip | Q35: 44816 | R35: -8.4 | U35: Kwik Trip | V35: 44843 | W35: -7.88 | Z35: Kwik Trip | AA35: 44875 | AB35: -6.81 | AE35: Kwik Trip | AF35: 44915 | AG35: -4.73 | AJ35: Kwik Trip | AK35: 44951 | AL35: -5.99 | AO35: Kwik Trip | AP35: 44975 | AQ35: -16.25 | AT35: Kwik Trip | AU35: 44997 | AV35: -8.82 | AY35: Kwik Trip | AZ35: 45043 | BA35: -5.26 | BD35: Kwik Trip | BE35: 45065 | BF35: -14.09
F36: Kwik Trip | G36: 44750 | H36: -5.39 | K36: Kwik Trip | L36: 44790 | M36: -5.99 | P36: Kwik Trip | Q36: 44817 | R36: -9.14 | U36: Kwik Trip | V36: 44844 | W36: -8.4 | Z36: Kwik Trip | AA36: 44877 | AB36: -13.99 | AE36: Kwik Trip | AF36: 44921 | AG36: -15.5 | AJ36: Kwik Trip | AK36: 44952 | AL36: -5.26 | AO36: Kwik Trip | AP36: 44977 | AQ36: -6.73 | AT36: Kwik Trip | AU36: 45000 | AV36: -3.14 | BA36: =SUM(BA27:BA35) -> -66.64 | BD36: Kwik Trip | BE36: 45068 | BF36: -16.37
F37: Kwik Trip | G37: 44751 | H37: -10.05 | K37: Kwik Trip | L37: 44793 | M37: -4.2 | P37: Kwik Trip | Q37: 44822 | R37: -2.62 | U37: Kwik Trip | V37: 44844 | W37: -7.58 | Z37: Kwik Trip | AA37: 44880 | AB37: -4.21 | AE37: Kwik Trip | AF37: 44921 | AG37: -22.63 | AJ37: Kwik Trip | AK37: 44955 | AL37: -12.41 | AO37: Kwik Trip | AP37: 44981 | AQ37: -5.26 | AT37: Kwik Trip | AU37: 45005 | AV37: -5.26 | BD37: Kwik Trip | BE37: 45071 | BF37: -6.99
A38: Gas Station Items | B38: Date | C38: Amount | D38: Notes | F38: Kwik Trip | G38: 44752 | H38: -17.94 | K38: Kwik Trip | L38: 44798 | M38: -18.99 | P38: Kwik Trip | Q38: 44824 | R38: -7.58 | U38: Kwik Trip | V38: 44845 | W38: -6.73 | Z38: Kwik Trip | AA38: 44882 | AB38: -5.25 | AE38: Kwik Trip | AF38: 44921 | AG38: -12.22 | AJ38: Kwik Trip | AK38: 44956 | AL38: -5.26 | AO38: Kwik Trip | AP38: 44984 | AQ38: -5.26 | AT38: Kwik Trip | AU38: 45005 | AV38: -11.25 | BD38: Kwik Trip | BE38: 45073 | BF38: -5.26
A39: Kwik Trip | B39: 44713 | C39: -9.27 | F39: Kwik Trip | G39: 44753 | H39: -4.52 | K39: Kwik Trip | L39: 44800 | M39: -4.31 | P39: Kwik Trip | Q39: 44824 | R39: -6.62 | U39: Kwik Trip | V39: 44852 | W39: -5.99 | Z39: Kwik Trip | AA39: 44883 | AB39: -2.62 | AE39: Kwik Trip | AF39: 44924 | AG39: -7.15 | AL39: =SUM(AL29:AL38) -> -128.69 | AO39: Kwik Trip | AP39: 44984 | AQ39: -7.79 | AT39: Kwik Trip | AU39: 45010 | AV39: -5.26 | AY39: Reg Store | AZ39: Date | BA39: Amount | BB39: Notes | BD39: Kwik Trip | BE39: 45073 | BF39: -5.26
A40: Kwik Trip | B40: 44714 | C40: -5.78 | F40: Kwik Trip | G40: 44753 | H40: -4.21 | K40: Kwik Trip | L40: 44803 | M40: -6.81 | P40: Kwik Trip | Q40: 44825 | R40: -3.37 | U40: Kwik Trip | V40: 44852 | W40: -7.56 | Z40: Kwik Trip | AA40: 44884 | AB40: -2.62 | AE40: Kwik Trip | AF40: 44925 | AG40: -5.26 | AQ40: =SUM(AQ30:AQ39) -> -72.41 | AT40: Kwik Trip | AU40: 45011 | AV40: -11.25 | AY40: Walmart | AZ40: 45020 | BA40: -19.51 | BF40: =SUM(BF29:BF39) -> -92.62
A41: Kwik Trip | B41: 44715 | C41: -6.64 | F41: Kwik Trip | G41: 44754 | H41: -2.31 | M41: =SUM(M30:M40) -> -85.89 | P41: Kwik Trip | Q41: 44828 | R41: -4.73 | U41: Kwik Trip | V41: 44854 | W41: -4.73 | Z41: Kwik Trip | AA41: 44886 | AB41: -4.21 | AE41: Kwik Trip | AF41: 44926 | AG41: -5.26 | AT41: Kwik Trip | AU41: 45012 | AV41: -5.26 | AY41: Walmart | AZ41: 45021 | BA41: -22.08
A42: Kwik Trip | B42: 44716 | C42: -4.21 | F42: Kwik Trip | G42: 44754 | H42: -8.83 | P42: Kwik Trip | Q42: 44829 | R42: -8.4 | U42: Kwik Trip | V42: 44854 | W42: -7.88 | Z42: Kwik Trip | AA42: 44888 | AB42: -6.81 | AG42: =SUM(AG30:AG41) -> -106.17 | AJ42: Reg Store | AK42: Date | AL42: Amount | AM42: Notes | AT42: Kwik Trip | AU42: 45013 | AV42: -8.82 | AY42: Office Depot | AZ42: 45026 | BA42: -10.54
A43: Kwik Trip | B43: 44719 | C43: -4.21 | F43: Kwik Trip | G43: 44755 | H43: -4.64 | P43: Kwik Trip | Q43: 44830 | R43: -3.37 | U43: Kwik Trip | V43: 44856 | W43: -8.4 | Z43: Kwik Trip | AA43: 44890 | AB43: -4.21 | AJ43: Publix | AK43: 44931 | AL43: -16.13 | AO43: Reg Store | AP43: Date | AQ43: Amount | AR43: Notes | AT43: Kwik Trip | AU43: 45014 | AV43: -14.78 | AY43: Walmart | AZ43: 45026 | BA43: -17.22 | BD43: Reg Store | BE43: Date | BF43: Amount | BG43: Notes
...

Sheet Work Hours 
A1: Fincancial Portfolio: Work Data
A2: Work Hours
A4: The Crow
A5: Month 1: June
A6: Work Dates: Daw | B6: Hours | C6: Wage Pay | D6: Notes
A7: Daw Mowing
A8: - 6/8/2022 | B8: 2 | C8: 40
A9: - Extra | C9: 25
C10: =SUM(C6:C9) -> 65
A12: 2022-23 | C12: $10 /hour | K12: 2023-24 | U12: Trust Point: Intern
A13: Month 1: June 2022 | C13: $8.50 /hour | K13: Month 1: June 2023 | M13: $8.50 /hour | U13: Month 1: March | W13: $14.00 /hour
A14: Work Dates: The Crow | B14: Hours | C14: Wage Pay | D14: Tips | E14: Tip Outs | F14: Avg Wage/Hour | G14: Total | H14: Notes | K14: Work Dates: The Crow | L14: Hours | M14: Wage Pay | N14: Tips | O14: Tip Outs | P14: Avg Wage/Hour | Q14: Total | R14: Notes | U14: Work Dates: | V14: Hours | W14: Wage Pay
A15: Week 43: 5/30 - 6/5 | K15: Week 95: 5/29 - 6/4 | U15: Week 1: 3/27 - 4/2
A16: - Mon 5/30 | B16: 6 | C16: =B16*8.5 -> 51 | D16: 45 | F16: =(C16+D16)/B16 -> 16 | G16: =C16+D16 -> 96 | K16: - Mon 5/29 | L16: 7.5 | M16: =L16*5 -> 37.5 | N16: 120 | P16: =(M16+N16)/L16 -> 21 | Q16: =M16+N16 -> 157.5 | U16: - Mon 3/27 | V16: 3.5 | W16: =V16*14 -> 49
A17: - Wed 6/1 | B17: 6 | C17: =B17*8.5 -> 51 | D17: 33 | F17: =(C17+D17)/B17 -> 14 | G17: =C17+D17 -> 84 | K17: - Tues 5/30 | L17: 6.5 | M17: =L17*5 -> 32.5 | N17: 88 | P17: =(M17+N17)/L17 -> 18.538462 | Q17: =M17+N17 -> 120.5 | U17: - Fri 3/31 | V17: 5 | W17: =V17*14 -> 70
A18: - Thurs 6/2 | B18: 6.5 | C18: =B18*14.5 -> 94.25 | D18: 47 | F18: =(C18+D18)/B18 -> 21.730769 | G18: =C18+D18 -> 141.25 | H18: - Dishwashed+Tips | K18: - Wed 5/31 | L18: 6 | M18: =L18*5 -> 30 | N18: 74 | P18: =(M18+N18)/L18 -> 17.333333 | Q18: =M18+N18 -> 104 | V18: =SUM(V16:V17) -> 8.5 | W18: =SUM(W16:W17) -> 119
B19: =SUM(B15:B18) -> 18.5 | C19: =SUM(C15:C18) -> 196.25 | D19: =SUM(D15:D18) -> 125 | E19: =SUM(E15:E18) -> 0 | F19: =(C19+D19)/B19 -> 17.364865 | G19: =C19+D19 -> 321.25 | K19: - Fri 6/2 | L19: 7.5 | M19: =L19*15 -> 112.5 | P19: =(M19+N19)/L19 -> 15 | Q19: =M19+N19 -> 112.5
A20: Week 44: 6/6 - 6/12 | K20: - Sun 6/4 | L20: 8.5 | M20: =(3.5*5)+(5*15) -> 92.5 | N20: 16 | P20: =(M20+N20)/L20 -> 12.764706 | Q20: =M20+N20 -> 108.5 | R20: - Double | U20: Total | V20: =V18 -> 8.5 | W20: =W18 -> 119
A21: - Tues 6/7 | B21: 6 | C21: =B21*8.5 -> 51 | D21: 53 | F21: =(C21+D21)/B21 -> 17.333333 | G21: =C21+D21 -> 104 | L21: =SUM(L15:L20) -> 36 | M21: =SUM(M15:M20) -> 305 | N21: =SUM(N15:N20) -> 298 | O21: =SUM(O15:O20) -> 0 | P21: =(M21+N21)/L21 -> 16.75 | Q21: =M21+N21 -> 603
A22: - Wed 6/8 | B22: 6.5 | C22: =B22*8.5 -> 55.25 | D22: 33 | F22: =(C22+D22)/B22 -> 13.576923 | G22: =C22+D22 -> 88.25 | H22: - Raise!! = $10/hour | K22: Week 96: 6/5 - 6/11
A23: - Fri 6/10 | B23: 7.5 | C23: =B23*8.5 -> 63.75 | D23: 67 | F23: =(C23+D23)/B23 -> 17.433333 | G23: =C23+D23 -> 130.75 | K23: - Wed 6/7 | L23: 6 | M23: =L23*5 -> 30 | N23: 119 | O23: 165 | P23: =(M23+N23)/L23 -> 24.833333 | Q23: =M23+N23 -> 149 | U23: Month 2: April | W23: $14.00 /hour
A24: - Sun 6/12 | B24: 4.5 | C24: =B24*8.5 -> 38.25 | D24: 24 | E24: 239 | F24: =(C24+D24)/B24 -> 13.833333 | G24: =C24+D24 -> 62.25 | H24: - Close Early, Meeting, Tip Out | K24: - Thurs 6/8 | L24: 5.5 | M24: =L24*15 -> 82.5 | P24: =(M24+N24)/L24 -> 15 | Q24: =M24+N24 -> 82.5 | U24: Work Dates: | V24: Hours | W24: Wage Pay
B25: =SUM(B21:B24) -> 24.5 | C25: =SUM(C21:C24) -> 208.25 | D25: =SUM(D21:D24) -> 177 | E25: =SUM(E21:E24) -> 239 | F25: =(C25+D25)/B25 -> 15.72449 | G25: =C25+D25 -> 385.25 | H25: 624.25 | K25: - Fri 6/9 | L25: 7 | M25: =L25*10 -> 70 | N25: 64 | P25: =(M25+N25)/L25 -> 19.142857 | Q25: =M25+N25 -> 134 | U25: Week 2: 4/3 - 4/9
A26: Week 45: 6/13 - 6/19 - Raise | K26: - Sun 6/11 | L26: 5.5 | M26: =L26*10 -> 55 | N26: 54 | P26: =(M26+N26)/L26 -> 19.818182 | Q26: =M26+N26 -> 109 | U26: - Mon 4/3 | V26: 1 | W26: =V26*14 -> 14
A27: - Tues 6/14 | B27: 6 | C27: =B27*10 -> 60 | D27: 56 | F27: =(C27+D27)/B27 -> 19.333333 | G27: =C27+D27 -> 116 | H27: - Paid: Start of Raise only $9.50 | L27: =SUM(L22:L26) -> 24 | M27: =SUM(M22:M26) -> 237.5 | N27: =SUM(N22:N26) -> 237 | O27: =SUM(O22:O26) -> 165 | P27: =(M27+N27)/L27 -> 19.770833 | Q27: =M27+N27 -> 474.5 | V27: =SUM(V26:V26) -> 1 | W27: =SUM(W26:W26) -> 14
A28: - Thurs 6/16 | B28: 5.5 | C28: =B28*14.5 -> 79.75 | D28: 0 | F28: =(C28+D28)/B28 -> 14.5 | G28: =C28+D28 -> 79.75 | K28: Week 97: 6/12 - 6/18
A29: - Fri 6/17 | B29: 6.5 | C29: =B29*10 -> 65 | D29: 49 | F29: =(C29+D29)/B29 -> 17.538462 | G29: =C29+D29 -> 114 | K29: - Wed 6/14 | L29: 5.5 | M29: =L29*15 -> 82.5 | P29: =(M29+N29)/L29 -> 15 | Q29: =M29+N29 -> 82.5 | U29: Total | V29: =V27 -> 1 | W29: =W27 -> 14
A30: - Sun 6/19 | B30: 4 | C30: =B30*10 -> 40 | D30: 33 | F30: =(C30+D30)/B30 -> 18.25 | G30: =C30+D30 -> 73 | K30: - Thurs 6/15 | L30: 7.5 | M30: =L30*5 -> 37.5 | N30: 118 | P30: =(M30+N30)/L30 -> 20.733333 | Q30: =M30+N30 -> 155.5
B31: =SUM(B27:B30) -> 22 | C31: =SUM(C27:C30) -> 244.75 | D31: =SUM(D27:D30) -> 138 | E31: =SUM(E27:E30) -> 0 | F31: =(C31+D31)/B31 -> 17.397727 | G31: =C31+D31 -> 382.75 | K31: - Fri 6/16 | L31: 5.5 | M31: =L31*10 -> 55 | N31: 41 | P31: =(M31+N31)/L31 -> 17.454545 | Q31: =M31+N31 -> 96
A32: Week 46: 6/20 - 6/26 | K32: - Sun 6/18 | L32: 6 | M32: =L32*15 -> 90 | P32: =(M32+N32)/L32 -> 15 | Q32: =M32+N32 -> 90
A33: - Tues 6/21 | B33: 6 | C33: =B33*10 -> 60 | D33: 51 | F33: =(C33+D33)/B33 -> 18.5 | G33: =C33+D33 -> 111 | H33: - Paid | L33: =SUM(L28:L32) -> 24.5 | M33: =SUM(M28:M32) -> 265 | N33: =SUM(N28:N32) -> 159 | O33: =SUM(O28:O32) -> 0 | P33: =(M33+N33)/L33 -> 17.306122 | Q33: =M33+N33 -> 424
A34: - Thurs 6/23 | B34: 6.5 | C34: =B34*10 -> 65 | D34: 60 | F34: =(C34+D34)/B34 -> 19.230769 | G34: =C34+D34 -> 125 | K34: Week 98: 6/19 - 6/25
A35: - Fri 6/24 | B35: 6.5 | C35: =B35*10 -> 65 | D35: 38 | F35: =(C35+D35)/B35 -> 15.846154 | G35: =C35+D35 -> 103 | K35: - Wed 6/22 | L35: 8 | M35: =L35*5 -> 40 | N35: 122 | P35: =(M35+N35)/L35 -> 20.25 | Q35: =M35+N35 -> 162
B36: =SUM(B33:B35) -> 19 | C36: =SUM(C33:C35) -> 190 | D36: =SUM(D33:D35) -> 149 | E36: =SUM(E33:E35) -> 0 | F36: =(C36+D36)/B36 -> 17.842105 | G36: =C36+D36 -> 339 | K36: - Thurs 6/23 | L36: 9 | M36: =L36*5 -> 45 | N36: 88 | O36: 94 | P36: =(M36+N36)/L36 -> 14.777778 | Q36: =M36+N36 -> 133
K37: - Sun 6/8 | L37: 2.5 | M37: =L37*7.5 -> 18.75 | P37: =(M37+N37)/L37 -> 7.5 | Q37: =M37+N37 -> 18.75 | R37: - Meeting
A38: Total | B38: =B19+B25+B31+B36 -> 84 | C38: =C19+C25+C31+C36 -> 839.25 | D38: =D19+D25+D31+D36 -> 589 | E38: =E19+E25+E31+E36 -> 239 | F38: =(C38+D38+E38)/B38 -> 19.848214 | G38: =C38+D38+E38 -> 1667.25 | L38: =SUM(L35:L37) -> 19.5 | M38: =SUM(M35:M37) -> 103.75 | N38: =SUM(N35:N37) -> 210 | O38: =SUM(O35:O37) -> 94 | P38: =(M38+N38)/L38 -> 16.089744 | Q38: =M38+N38 -> 313.75
K39: Week 99: 6/26 - 7/2
K40: - Mon 6/26 | L40: 5.5 | M40: =L40*15 -> 82.5 | P40: =(M40+N40)/L40 -> 15 | Q40: =M40+N40 -> 82.5 | R40: - Paid
A41: Month 2: July 2022 | K41: - Thurs 6/29 | L41: 8.5 | M41: =L41*5 -> 42.5 | N41: 108 | P41: =(M41+N41)/L41 -> 17.705882 | Q41: =M41+N41 -> 150.5
A42: Work Dates: Daw | B42: Hours | C42: Wage Pay | D42: Notes | K42: - Fri 6/30 | L42: 7 | M42: =L42*15 -> 105 | O42: 75 | P42: =(M42+N42)/L42 -> 15 | Q42: =M42+N42 -> 105 | R42: Tip Out
...

Sheet Crypto Claims
A1: Fincancial Portfolio: Crypto Claims
A2: Earning Claims
A4: Crypto Staking
A5: SweatCoin
A6: Staking | B6: Date Staked | C6: Coin | D6: Price at Stake (Coin) | E6: Start Amount (Coin) | F6: Start Amount ($) | G6: Current APR | H6: Current APR Amount (Daily)
A7: Sweat Wallet
A8: Asset 1 | B8: 45283
A11: HoneyGain: JumbTask | G11: Fluid Starter: 2.1%
A12: Staking | B12: Date Staked | C12: Coin | D12: Price at Stake (Coin) | E12: Start Amount (Coin) | F12: Start Amount ($) | G12: Current APR | H12: Current APR Amount (Daily)
A13: HoneyGain: JumbTask | N13: 4
A14: Asset 1 | B14: 44951 | C14: JMPT | D14: 2.19 | E14: 23.24261 | F14: =E14*D14 -> 50.901316 | G14: 0.021 | H14: =(B23*G14)/365 -> 0.0019234878 | N14: 5
A16: Interest Earned Claims | F16: Data Claims | M16: 6
A17: New Claim Date | B17: Claim Amount (Coin) | C17: Earnings off Interest (Coin) | D17: Earnings off Interest ($) | F17: New Claim Date | G17: Claim Amount (Coin) | H17: Earnings off Interest (Coin)
A18: 11/1/2023: Start | B18: 8.9 | C18: =E14+B18 -> 32.14261 | D18: =C18*'Crypto Market Price Data'!C34 -> 23.953894 | F18: 45231 | G18: 1.28944 | H18: =G18+'Crypto Market Price Data'!C34 -> 2.034678
A21: Data Claims
A22: New Claim Date | B22: New Amount (Coin) | C22: New Amount ($)
A23: 45231 | B23: =C18+G18 -> 33.43205 | C23: =B23*'Crypto Market Price Data'!C34 -> 24.914834
A27: Axie Infinity | E27: Actual today - | F27: =E30*'Crypto Market Price Data'!$C$19 -> 9.3733477 | G27: 44704
A28: Staking | B28: Date Staked | C28: Coin | D28: Price at Purchase (Coin) | E28: Start Amount (Coin) | F28: Amount ($) | G28: Current APR | H28: Current APR Amount (Daily) | I28: Column1
A29: Ronin Staking
A30: Asset 1 | B30: 44592 | C30: AXS | D30: 52.3 | E30: 9.4185 | F30: ='Crypto Claims'!$E30*'Crypto Claims'!$D30 -> 492.58755 | G30: 0.35 | H30: =(B77*'Crypto Claims'!$G30)/365 -> 0.14091969 | I30: ='Crypto Claims'!$H30*3 -> 0.42275908
A32: Interest Earned Claims | F32: Land Claims
A33: New Claim Date | B33: Claim Amount (Coin) | C33: Earnings off Interest (Coin) | D33: Earnings off Interest ($) | F33: New Claim Date | G33: Claim Amount (Coin) | H33: Earnings off Land (Coin) | I33: Earnings off Land ($)
A34: 44616 | B34: 0.5148 | C34: =E30+B34 -> 9.9333 | D34: =C34*'Crypto Market Price Data'!$C$19 -> 9.8856798 | F34: 44783 | G34: 10.47799 | H34: ='Crypto Claims'!$G34 -> 10.47799 | I34: ='Crypto Claims'!$H34*'Crypto Market Price Data'!$C$19 -> 10.427759
A35: 44645 | B35: 0.5672 | C35: =C34+B35 -> 10.5005 | D35: =C35*'Crypto Market Price Data'!$C$19 -> 10.450161 | F35: 44805 | G35: 5.722203 | H35: =H34+'Crypto Claims'!$G35 -> 16.200193 | I35: ='Crypto Claims'!$H35*'Crypto Market Price Data'!$C$19 -> 16.122529
A36: 44675 | B36: 0.6503 | C36: =C35+B36 -> 11.1508 | D36: =C36*'Crypto Market Price Data'!$C$19 -> 11.097343 | F36: 44835 | G36: 7.638457 | H36: =H35+'Crypto Claims'!$G36 -> 23.83865 | I36: ='Crypto Claims'!$H36*'Crypto Market Price Data'!$C$19 -> 23.724368
A37: 44704 | B37: 0.6863 | C37: =C36+B37 -> 11.8371 | D37: =C37*'Crypto Market Price Data'!$C$19 -> 11.780353 | F37: 44866 | G37: 8.043623 | H37: =H36+'Crypto Claims'!$G37 -> 31.882273 | I37: ='Crypto Claims'!$H37*'Crypto Market Price Data'!$C$19 -> 31.729429
A38: 44742 | B38: 1.0035 | C38: =C37+B38 -> 12.8406 | D38: =C38*'Crypto Market Price Data'!$C$19 -> 12.779042 | F38: 44896 | G38: 7.7224013 | H38: =H37+'Crypto Claims'!$G38 -> 39.604674 | I38: ='Crypto Claims'!$H38*'Crypto Market Price Data'!$C$19 -> 39.414809
A39: 44783 | B39: 1.013614 | C39: =C38+B39 -> 13.854214 | D39: =C39*'Crypto Market Price Data'!$C$19 -> 13.787797 | F39: 44941 | G39: 11.58258 | H39: =H38+'Crypto Claims'!$G39 -> 51.187254 | I39: ='Crypto Claims'!$H39*'Crypto Market Price Data'!$C$19 -> 50.941863
A40: 44805 | B40: 0.913346 | C40: =C39+B40 -> 14.76756 | D40: =C40*'Crypto Market Price Data'!$C$19 -> 14.696764 | F40: 44958 | G40: 4.810596 | H40: =H39+'Crypto Claims'!$G40 -> 55.99785 | I40: ='Crypto Claims'!$H40*'Crypto Market Price Data'!$C$19 -> 55.729397
A41: 44835 | B41: 1.525835 | C41: =C40+B41 -> 16.293395 | D41: =C41*'Crypto Market Price Data'!$C$19 -> 16.215284 | F41: 44986 | G41: 6.301217 | H41: =H40+'Crypto Claims'!$G41 -> 62.299067 | I41: ='Crypto Claims'!$H41*'Crypto Market Price Data'!$C$19 -> 62.000406
A42: 44866 | B42: 1.691947 | C42: =C41+B42 -> 17.985342 | D42: =C42*'Crypto Market Price Data'!$C$19 -> 17.89912 | F42: 45017 | G42: 8.463442 | H42: =H41+'Crypto Claims'!$G42 -> 70.762509 | I42: ='Crypto Claims'!$H42*'Crypto Market Price Data'!$C$19 -> 70.423274
A43: 44896 | B43: 1.868694 | C43: =C42+B43 -> 19.854036 | D43: =C43*'Crypto Market Price Data'!$C$19 -> 19.758856 | F43: 45047 | G43: 7.824492 | H43: =H42+'Crypto Claims'!$G43 -> 78.587001 | I43: ='Crypto Claims'!$H43*'Crypto Market Price Data'!$C$19 -> 78.210255
A44: 44941 | B44: 3.207299 | C44: =C43+B44 -> 23.061335 | D44: =C44*'Crypto Market Price Data'!$C$19 -> 22.950779 | F44: 45078 | G44: 8.421743 | H44: =H43+'Crypto Claims'!$G44 -> 87.008744 | I44: ='Crypto Claims'!$H44*'Crypto Market Price Data'!$C$19 -> 86.591624
A45: 44958 | B45: 1.614265 | C45: =C44+B45 -> 24.6756 | D45: =C45*'Crypto Market Price Data'!$C$19 -> 24.557305 | F45: 45108 | G45: 7.333692 | H45: =H44+'Crypto Claims'!$G45 -> 94.342436 | I45: ='Crypto Claims'!$H45*'Crypto Market Price Data'!$C$19 -> 93.890159
A46: 44986 | B46: 2.31195 | C46: =C45+B46 -> 26.98755 | D46: =C46*'Crypto Market Price Data'!$C$19 -> 26.858172 | F46: 45139 | G46: 8.027721 | H46: =H45+'Crypto Claims'!$G46 -> 102.37016 | I46: ='Crypto Claims'!$H46*'Crypto Market Price Data'!$C$19 -> 101.87939
... A52: 45170 | B52: 4.354191 | C52: =C51+B52 -> 48.943143 | D52: =C52*'Crypto Market Price Data'!$C$19 -> 48.70851 | F52: 45323 | G52: 4.445978 | H52: =H51+'Crypto Claims'!$G52 -> 140.75708 | I52: ='Crypto Claims'!$H52*'Crypto Market Price Data'!$C$19 -> 140.08229
A53: 45200 | B53: 4.60166 | C53: =C52+B53 -> 53.544803 | D53: =C53*'Crypto Market Price Data'!$C$19 -> 53.288109 | F53: 45352 | G53: 0 | H53: =H52+'Crypto Claims'!$G53 -> 140.75708 | I53: ='Crypto Claims'!$H53*'Crypto Market Price Data'!$C$19 -> 140.08229 | J53: - Earnings Stopped
A54: 45231 | B54: 5.581678 | C54: =C53+B54 -> 59.126481 | D54: =C54*'Crypto Market Price Data'!$C$19 -> 58.843029 | F54: 45383 | G54: 0 | H54: =H53+'Crypto Claims'!$G54 -> 140.75708 | I54: ='Crypto Claims'!$H54*'Crypto Market Price Data'!$C$19 -> 140.08229
A55: 45261 | B55: 4.946516 | C55: =C54+B55 -> 64.072997 | D55: =C55*'Crypto Market Price Data'!$C$19 -> 63.765831 | F55: 45424 | G55: 0 | H55: =H54+'Crypto Claims'!$G55 -> 140.75708 | I55: ='Crypto Claims'!$H55*'Crypto Market Price Data'!$C$19 -> 140.08229
...

Sheet General Crypto Earnings
A1: Fincancial Portfolio: Crypto Earnings
A2: General Crypto Earnings
A5: GPU & CPU Miners:
A6: Miner Website: | B6: Wallet | C6: Coin | D6: Mh (Average) | E6: Profit/Day (Coin) | F6: Profit/Week (Coin) | G6: Profit/Month (Coin) | H6: Profit/Year (Coin) | I6: Profit/Day ($) | J6: Profit/Week ($) | K6: Profit/Month ($) | L6: Profit/Year ($)
A7: Unmineable: SHIBA | B7: Atomic: 0x0C203Fcf60F1e7B6224D1f44641e51715f4C434D | C7: SHIBA | D7: 23.1 | E7: 15037.213 | F7: =Table27[[#This Row],[Profit/Day (Coin)]]*7 -> 105260.49 | G7: =Table27[[#This Row],[Profit/Day (Coin)]]*30 -> 451116.4 | H7: =Table27[[#This Row],[Profit/Month (Coin)]]*12 -> 5413396.8 | I7: =Table27[[#This Row],[Profit/Day (Coin)]]*'Crypto Market Price Data'!$C$10 -> 0.11879398 | J7: =Table27[[#This Row],[Profit/Week (Coin)]]*'Crypto Market Price Data'!$C$10 -> 0.83155789 | K7: =Table27[[#This Row],[Profit/Month (Coin)]]*'Crypto Market Price Data'!$C$10 -> 3.5638195 | L7: =Table27[[#This Row],[Profit/Year (Coin)]]*'Crypto Market Price Data'!$C$10 -> 42.765834
H9: Avg. Total: | I9: =I7 -> 0.11879398 | J9: =J7 -> 0.83155789 | K9: =K7 -> 3.5638195 | L9: =L7 -> 42.765834
A11: Exchange Miners:
A12: Miner Website: | B12: Wallet | C12: Coin | D12: Miner Level | E12: Profit/Day (Coin) | F12: Profit/Week (Coin) | G12: Profit/Month (Coin) | H12: Profit/Year (Coin) | I12: Profit/Day ($) | J12: Profit/Week ($) | K12: Profit/Month ($) | L12: Profit/Year ($)
A13: StormGain | B13: In-App | C13: BTC | D13: 1 | E13: 1.08e-05 | F13: =Table28[[#This Row],[Profit/Day (Coin)]]*7 -> 7.56e-05 | G13: =Table28[[#This Row],[Profit/Day (Coin)]]*30 -> 0.000324 | H13: =Table28[[#This Row],[Profit/Month (Coin)]]*12 -> 0.003888 | I13: =Table28[[#This Row],[Profit/Day (Coin)]]*'Crypto Market Price Data'!$C$5 -> 0.917946 | J13: =Table28[[#This Row],[Profit/Week (Coin)]]*'Crypto Market Price Data'!$C$5 -> 6.425622 | K13: =Table28[[#This Row],[Profit/Month (Coin)]]*'Crypto Market Price Data'!$C$5 -> 27.53838 | L13: =Table28[[#This Row],[Profit/Year (Coin)]]*'Crypto Market Price Data'!$C$5 -> 330.46056 | M13: x5 + 15% of referals
H15: Avg. Total: | I15: =I13 -> 0.917946 | J15: =J13 -> 6.425622 | K15: =K13 -> 27.53838 | L15: =L13 -> 330.46056 | M15: with 15% every month
A17: Data Miners:
A18: Miner Website: | B18: Wallet | C18: Coin | D18: Referrals | E18: Profit/Day (Coin) | F18: Profit/Week (Coin) | G18: Profit/Month (Coin) | H18: Profit/Year (Coin) | I18: Profit/Day ($) | J18: Profit/Week ($) | K18: Profit/Month ($) | L18: Profit/Year ($)
A19: HoneyGain
A20: - Asset 1: HoneyGain | B20: In-App | C20: BTC | D20: 3 | E20: 120 | F20: =Table29[[#This Row],[Profit/Day (Coin)]]*7 -> 840 | G20: =Table29[[#This Row],[Profit/Day (Coin)]]*30 -> 3600 | H20: =Table29[[#This Row],[Profit/Month (Coin)]]*12 -> 43200 | I20: 0.12 | J20: 0.84 | K20: 3.6 | L20: 43.8
A21: - Asset 2: JumpTask | B21: In-App | C21: JMPT | D21: 3 | E21: 0.09 | F21: =Table29[[#This Row],[Profit/Day (Coin)]]*7 -> 0.63 | G21: =Table29[[#This Row],[Profit/Day (Coin)]]*30 -> 2.7 | H21: =Table29[[#This Row],[Profit/Month (Coin)]]*12 -> 32.4 | I21: =Table29[[#This Row],[Profit/Day (Coin)]]*'Crypto Market Price Data'!$C$34 -> 0.06707142 | J21: =Table29[[#This Row],[Profit/Week (Coin)]]*'Crypto Market Price Data'!$C$34 -> 0.46949994 | K21: =Table29[[#This Row],[Profit/Month (Coin)]]*'Crypto Market Price Data'!$C$34 -> 2.0121426 | L21: =Table29[[#This Row],[Profit/Year (Coin)]]*'Crypto Market Price Data'!$C$34 -> 24.145711
H22: Avg. Total: | I22: =SUM(I20:I21) -> 0.18707142 | J22: =SUM(J20:J21) -> 1.3094999 | K22: =SUM(K20:K21) -> 5.6121426 | L22: =SUM(L20:L21) -> 67.945711
A24: Other Miners
A25: Other Miners | B25: Wallet | C25: Coin | D25: Profit/Day ($) | E25: Profit/Week($) | F25: Profit/Month ($) | G25: Profit/Year ($)
A26: Kryptex | B26: In-App | C26: Dollars | D26: 0.4 | E26: =Table30[[#This Row],[Profit/Day ($)]]*7 -> 2.8 | F26: =Table30[[#This Row],[Profit/Day ($)]]*30 -> 12 | G26: =Table30[[#This Row],[Profit/Month ($)]]*12 -> 144
C27: Avg. Total | D27: {=Table30[Profit/Day ($)]} -> 0.4 | E27: {=Table30[Profit/Week($)]} -> 2.8 | F27: {=Table30[Profit/Month ($)]} -> 12 | G27: {=Table30[Profit/Year ($)]} -> 144
A29: NFT Accounts:
A30: NFT Website | B30: Coin | C30: Profit/Day (Coin) | D30: Profit/Week (Coin) | E30: Profit/Month (Coin) | F30: Profit/Year (Coin) | G30: Profit/Day ($) | H30: Profit/Week($) | I30: Profit/Month ($) | J30: Profit/Year ($)
